Workbook

Sheet 全部菌密码子
B1: ASV45:s_unclassified_g__Escherichia-Shigella | C1: ASV1833:s_unclassified_g__Enterococcus | D1: ASV3729:s_Cloacibacillus_porcorum | E1: ASV31:s_Lactobacillus_vaginalis_g__Bacillus | F1: ASV17:s_uncultured_bacterium_g__Sharpea | G1: ASV9:s_unclassified_g__Romboutsia | H1: ASV73:s_unclassified_g__Turicibacter | I1: ASV1517:s_unclassified_g__Escherichia-Shigella | J1: ASV7:s_unclassified_g__Lactobacillus | K1: ASV30:s_unclassified_g__Clostridium_sensu_stricto_1 | L1: ASV21:s_Clostridium_scindens | M1: ASV54:s_unclassified_g__Clostridium_sensu_stricto_1 | N1: ASV33:s_gut_metagenome_g__norank_f__norank | O1: ASV1834:s_unclassified_f__Lachnospiraceae | P1: ASV28:s_uncultured_prokaryote_g__Christensenellaceae_R-7_group | Q1: ASV3787:s_uncultured_organism_g__UCG-002 | R1: ASV8:s_unclassified_g__Coprococcus | S1: ASV4:s_uncultured_spirochete_g__Christensenellaceae_R-7_group | T1: ASV1831:s_Eubacterium_coprostanoligenes | U1: ASV1555:s_unclassified_g__Enterococcus | V1: ASV1853:s_unclassified_g__Lactobacillus | W1: ASV22:s_unclassified_g__Lactobacillus | X1: ASV7036:s_unclassified_g__Bacteroides | Y1: ASV2:s_unclassified_g__Lactobacillus | Z1: ASV77:s_unclassified_g__Lactobacillus | AA1: ASV167:s_unclassified_g__Collinsella | AB1: ASV1540:s_unclassified_g__Megasphaera | AC1: ASV3402:s_unclassified_g__Megasphaera | AD1: ASV2874:s_unclassified_g__Fusobacterium | AE1: ASV2996:s_unclassified_g__Fusobacterium | AF1: ASV318:s_unclassified_g__Peptostreptococcus | AG1: ASV2586:s_unclassified_g__Campylobacter | AH1: ASV1515:s_unclassified_g__Streptococcus | AI1: ASV5:s_unclassified_g__UCG-002 | AJ1: ASV2860:s_unclassified_g__Phascolarctobacterium | AK1: ASV48:s_unclassified_g__Blautia | AL1: ASV38:s_unclassified_g__Blautia | AM1: ASV2839:s_Pasteurella_aerogenes | AN1: ASV1527:s_Lactobacillus_vaginalis_g__Bacillus | AO1: ASV172:s_uncultured_bacterium_g__Mogibacterium | AP1: ASV1089:s_Fusobacterium_gastrosuis | AQ1: ASV3058:s_uncultured_bacterium_g__Allisonella | AR1: H6_PBMC | AS1: H7_PBMC | AT1: W10_PBMC | AU1: W6_PBMC
A2: AAA | B2: 1.5344933 | C2: 1.552725 | D2: 0 | E2: 1.0956245 | F2: 1.1003009 | G2: 1.5187491 | H2: 1.5591946 | I2: 1.5296648 | J2: 1.2350621 | K2: 1.3844375 | L2: 0.86034145 | M2: 1.4183298 | N2: 1.1789639 | O2: 1.1190215 | P2: 1.1158873 | Q2: 0.45727555 | R2: 1.2088429 | S2: 1.0443849 | T2: 1.1214768 | U2: 1.552149 | V2: 0.50928423 | W2: 0.8899004 | X2: 1.2818064 | Y2: 0.94544423 | Z2: 0.51771298 | AA2: 0.32621684 | AB2: 1.0685378 | AC2: 1.0705512 | AD2: 1.6205278 | AE2: 1.5278473 | AF2: 1.2526677 | AG2: 1.6783762 | AH2: 1.5970184 | AI2: 1.4902614 | AJ2: 0.92982259 | AK2: 1.3642961 | AL2: 1.2745115 | AM2: 1.7985108 | AN2: 0.8443391 | AO2: 0.75492687 | AP2: 1.6843118 | AQ2: 0.88084687 | AR2: 0.82420333 | AS2: 0.84761225 | AT2: 0.72913694 | AU2: 0.72889925
A3: AAC | B3: 1.1056573 | C3: 0.44191523 | D3: 1.3276645 | E3: 0 | F3: 0.44965649 | G3: 0.33113056 | H3: 0.41820066 | I3: 1.0947583 | J3: 0.49387857 | K3: 0.34829941 | L3: 0.74777448 | M3: 0.2615033 | N3: 0.23711186 | O3: 0.83726107 | P3: 1.0548613 | Q3: 1.6368538 | R3: 0.66831659 | S3: 0.95215697 | T3: 0.93924179 | U3: 0.44187311 | V3: 1.3166014 | W3: 0.9463945 | X3: 0.80780773 | Y3: 0.83513347 | Z3: 1.2931713 | AA3: 1.5653435 | AB3: 1.0367471 | AC3: 1.0558359 | AD3: 0.30417004 | AE3: 0.41853426 | AF3: 0.46567213 | AG3: 0.2755878 | AH3: 0.5642554 | AI3: 0.93756226 | AJ3: 0.9635142 | AK3: 0.63390209 | AL3: 0.65698822 | AM3: 0.57416653 | AN3: 0.76651457 | AO3: 1.1311703 | AP3: 0.26299282 | AQ3: 0.71951558 | AR3: 1.0953025 | AS3: 1.0755309 | AT3: 1.2093849 | AU3: 1.2117844
A4: AAG | B4: 0.4655067 | C4: 0.44727505 | D4: 0 | E4: 0.90437554 | F4: 0.8996991 | G4: 0.48125091 | H4: 0.44080537 | I4: 0.4703352 | J4: 0.76493793 | K4: 0.61556252 | L4: 1.1396586 | M4: 0.58167015 | N4: 0.82103611 | O4: 0.88097848 | P4: 0.8841127 | Q4: 1.5427245 | R4: 0.79115708 | S4: 0.95561514 | T4: 0.87852324 | U4: 0.44785105 | V4: 1.4907158 | W4: 1.1100996 | X4: 0.71819363 | Y4: 1.0545558 | Z4: 1.482287 | AA4: 1.6737832 | AB4: 0.93146217 | AC4: 0.92944883 | AD4: 0.37947216 | AE4: 0.47215268 | AF4: 0.74733231 | AG4: 0.32162383 | AH4: 0.4029816 | AI4: 0.5097386 | AJ4: 1.0701774 | AK4: 0.63570392 | AL4: 0.72548854 | AM4: 0.2014892 | AN4: 1.1556609 | AO4: 1.2450731 | AP4: 0.31568819 | AQ4: 1.1191531 | AR4: 1.1757967 | AS4: 1.1523878 | AT4: 1.2708631 | AU4: 1.2711007
A5: AAT | B5: 0.89434271 | C5: 1.5580848 | D5: 0.6723355 | E5: 0 | F5: 1.5503435 | G5: 1.6688694 | H5: 1.5817993 | I5: 0.90524175 | J5: 1.5061214 | K5: 1.6517006 | L5: 1.2522255 | M5: 1.7384967 | N5: 1.7628881 | O5: 1.1627389 | P5: 0.94513874 | Q5: 0.36314621 | R5: 1.3316834 | S5: 1.047843 | T5: 1.0607582 | U5: 1.5581269 | V5: 0.68339855 | W5: 1.0536055 | X5: 1.1921923 | Y5: 1.1648665 | Z5: 0.70682875 | AA5: 0.43465653 | AB5: 0.9632529 | AC5: 0.9441641 | AD5: 1.69583 | AE5: 1.5814657 | AF5: 1.5343279 | AG5: 1.7244122 | AH5: 1.4357446 | AI5: 1.0624377 | AJ5: 1.0364858 | AK5: 1.3660979 | AL5: 1.3430118 | AM5: 1.4258335 | AN5: 1.2334854 | AO5: 0.86882972 | AP5: 1.7370072 | AQ5: 1.2804844 | AR5: 0.90469753 | AS5: 0.92446909 | AT5: 0.79061514 | AU5: 0.78821564
A6: ACA | B6: 0.51469138 | C6: 1.2775862 | D6: 0 | E6: 0 | F6: 2.2324906 | G6: 1.7933592 | H6: 1.7010858 | I6: 0.52534263 | J6: 1.0469924 | K6: 1.6724142 | L6: 1.0441376 | M6: 1.8077399 | N6: 1.7989976 | O6: 0.87104425 | P6: 0.79379342 | Q6: 0.21643251 | R6: 1.695286 | S6: 0.82251533 | T6: 1.9253987 | U6: 1.2742812 | V6: 0.31146774 | W6: 0.36462414 | X6: 1.0646685 | Y6: 0.7603421 | Z6: 0.31869402 | AA6: 0.2060243 | AB6: 0.51982011 | AC6: 0.50972855 | AD6: 1.7680812 | AE6: 1.441668 | AF6: 1.7432823 | AG6: 1.2536876 | AH6: 1.7040754 | AI6: 1.8633721 | AJ6: 0.77867461 | AK6: 1.8813726 | AL6: 1.8431514 | AM6: 0.78504673 | AN6: 0.97127704 | AO6: 0.59505286 | AP6: 1.972937 | AQ6: 1.0422389 | AR6: 1.075281 | AS6: 1.097374 | AT6: 0.95089291 | AU6: 0.94136558
A7: ACC | B7: 1.7506286 | C7: 0.76143335 | D7: 0 | E7: 0 | F7: 0.35337741 | G7: 0.12223404 | H7: 0.45786628 | I7: 1.7348147 | J7: 0.45526833 | K7: 0.25379995 | L7: 1.1443052 | M7: 0.14512864 | N7: 0.41382856 | O7: 1.6153628 | P7: 0.92791865 | Q7: 2.8040785 | R7: 0.89875482 | S7: 1.3480238 | T7: 0.80722073 | U7: 0.76117119 | V7: 1.6818394 | W7: 1.1420238 | X7: 1.1646848 | Y7: 0.7357618 | Z7: 1.6638255 | AA7: 2.0034393 | AB7: 1.3025976 | AC7: 1.3097075 | AD7: 0.12168678 | AE7: 0.72801925 | AF7: 0.29052382 | AG7: 0.72013285 | AH7: 0.53819373 | AI7: 1.1400634 | AJ7: 1.4469099 | AK7: 0.71101927 | AL7: 0.80768374 | AM7: 1.4485119 | AN7: 0.89344707 | AO7: 1.9434114 | AP7: 0.16483179 | AQ7: 1.5702854 | AR7: 1.4166976 | AS7: 1.3920074 | AT7: 1.578409 | AU7: 1.5754043
A8: ACG | B8: 1.0725052 | C8: 0.78112741 | D8: 0 | E8: 0 | F8: 0.46363283 | G8: 0.16386877 | H8: 0.91863379 | I8: 1.0806369 | J8: 0.31045558 | K8: 0.060896423 | L8: 1.2672999 | M8: 0.11871302 | N8: 0.21616759 | O8: 1.096354 | P8: 1.9430625 | Q8: 0.83626771 | R8: 0.73897278 | S8: 1.2650393 | T8: 0.34964899 | U8: 0.78259035 | V8: 0.79565327 | W8: 1.6469848 | X8: 0.70528006 | Y8: 0.50490972 | Z8: 0.78243282 | AA8: 1.5072946 | AB8: 1.7919442 | AC8: 1.7868934 | AD8: 0.041343669 | AE8: 0.71942261 | AF8: 0.45502387 | AG8: 0.28348149 | AH8: 0.64233054 | AI8: 0.43375617 | AJ8: 0.78165302 | AK8: 0.62132042 | AL8: 0.46648107 | AM8: 0.77239396 | AN8: 0.63043548 | AO8: 1.004361 | AP8: 0.14669893 | AQ8: 0.65559935 | AR8: 0.55933646 | AS8: 0.53974269 | AT8: 0.64597244 | AU8: 0.66047694
A9: ACT | B9: 0.66217474 | C9: 1.1798531 | D9: 0 | E9: 0 | F9: 0.95049916 | G9: 1.920538 | H9: 0.92241417 | I9: 0.6592058 | J9: 2.1872837 | K9: 2.0128894 | L9: 0.54425732 | M9: 1.9284184 | N9: 1.5710063 | O9: 0.41723894 | P9: 0.3352254 | Q9: 0.14322129 | R9: 0.66698643 | S9: 0.56442162 | T9: 0.91773155 | U9: 1.1819573 | V9: 1.2110395 | W9: 0.8463672 | X9: 1.0653666 | Y9: 1.9989864 | Z9: 1.2350477 | AA9: 0.2832418 | AB9: 0.3856381 | AC9: 0.39367052 | AD9: 2.0688884 | AE9: 1.1108901 | AF9: 1.51117 | AG9: 1.7426981 | AH9: 1.1154004 | AI9: 0.56280832 | AJ9: 0.99276247 | AK9: 0.78628773 | AL9: 0.88268374 | AM9: 0.99404745 | AN9: 1.5048404 | AO9: 0.45717475 | AP9: 1.7155322 | AQ9: 0.73187627 | AR9: 0.94868493 | AS9: 0.97087592 | AT9: 0.82472566 | AU9: 0.82275323
A10: AGA | B10: 0.21333008 | C10: 1.1085595 | D10: 0 | E10: 0.46743804 | F10: 2.1507092 | G10: 4.9494198 | H10: 1.0592135 | I10: 0.22055788 | J10: 1.9959153 | K10: 5.1465397 | L10: 1.4813218 | M10: 4.9301618 | N10: 3.4057454 | O10: 1.0439228 | P10: 0.56284348 | Q10: 0.13977768 | R10: 1.9790772 | S10: 0.76583682 | T10: 2.8377993 | U10: 1.1081948 | V10: 0.97058824 | W10: 0.42386003 | X10: 0.82834924 | Y10: 1.7803473 | Z10: 1.0101963 | AA10: 0.090549592 | AB10: 0.24602622 | AC10: 0.24292563 | AD10: 5.3436626 | AE10: 3.0704132 | AF10: 4.4608331 | AG10: 3.1309334 | AH10: 0.69197442 | AI10: 1.625922 | AJ10: 0.79962936 | AK10: 2.038995 | AL10: 2.1077663 | AM10: 0.41943872 | AN10: 0.43845743 | AO10: 1.1297387 | AP10: 5.0807683 | AQ10: 1.3217935 | AR10: 1.214156 | AS10: 1.2785368 | AT10: 1.0274827 | AU10: 1.0239431
A11: AGC | B11: 1.6704955 | C11: 0.70664202 | D11: 0 | E11: 0 | F11: 0.76668833 | G11: 0.46283478 | H11: 0.41793973 | I11: 1.658763 | J11: 0.64170564 | K11: 0.51752079 | L11: 1.5822501 | M11: 0.49070632 | N11: 0.86965398 | O11: 1.6090639 | P11: 1.7633126 | Q11: 2.018353 | R11: 1.034682 | S11: 1.242341 | T11: 1.2037545 | U11: 0.70701701 | V11: 2.0319047 | W11: 1.4182496 | X11: 0.92798815 | Y11: 0.90089474 | Z11: 2.0016269 | AA11: 1.6064423 | AB11: 1.6467848 | AC11: 1.6248377 | AD11: 0.32473735 | AE11: 0.66604423 | AF11: 0.67258258 | AG11: 1.3385707 | AH11: 0.84659977 | AI11: 1.4932739 | AJ11: 2.2699561 | AK11: 0.95723847 | AL11: 1.0350585 | AM11: 1.1051922 | AN11: 0.7876251 | AO11: 1.4975636 | AP11: 0.39546064 | AQ11: 1.0489909 | AR11: 1.4353908 | AS11: 1.4128015 | AT11: 1.604821 | AU11: 1.6032355
A12: AGG | B12: 0.11825465 | C12: 0.20936475 | D12: 0 | E12: 0.20944414 | F12: 0.32291667 | G12: 0.59569674 | H12: 0.22083348 | I12: 0.12766633 | J12: 0.27407223 | K12: 0.58369413 | L12: 1.3433801 | M12: 0.63620878 | N12: 0.76179493 | O12: 1.2335059 | P12: 0.9292184 | Q12: 0.47153372 | R12: 0.5749934 | S12: 0.83352296 | T12: 0.48707785 | U12: 0.21027515 | V12: 0.32506394 | W12: 0.15049934 | X12: 0.42399547 | Y12: 0.20327544 | Z12: 0.32781035 | AA12: 0.25905899 | AB12: 0.20042869 | AC12: 0.19574369 | AD12: 0.39143533 | AE12: 0.48132231 | AF12: 0.92821588 | AG12: 0.58489965 | AH12: 0.19781308 | AI12: 0.27879344 | AJ12: 0.3270601 | AK12: 0.50693536 | AL12: 0.70199645 | AM12: 0.060180338 | AN12: 0.24020306 | AO12: 0.18943858 | AP12: 0.50975306 | AQ12: 0.59285972 | AR12: 1.1964193 | AS12: 1.2143534 | AT12: 1.208372 | AU12: 1.2079256
A13: AGT | B13: 0.9021513 | C13: 1.7672887 | D13: 0 | E13: 0 | F13: 1.4540227 | G13: 1.8204617 | H13: 1.5965562 | I13: 0.91770624 | J13: 1.7109246 | K13: 1.7464985 | L13: 0.69048899 | M13: 1.8811042 | N13: 1.6731653 | O13: 0.68506088 | P13: 0.57562415 | Q13: 0.19554541 | R13: 1.197236 | S13: 0.49089058 | T13: 0.66554503 | U13: 1.7665553 | V13: 0.60804501 | W13: 1.0685248 | X13: 1.148847 | Y13: 1.3710078 | Z13: 0.63358641 | AA13: 0.28282774 | AB13: 0.6601586 | AC13: 0.64817833 | AD13: 1.8883886 | AE13: 1.3861916 | AF13: 1.2327629 | AG13: 1.9333293 | AH13: 1.2730417 | AI13: 0.80998363 | AJ13: 0.80542419 | AK13: 1.254657 | AL13: 1.1535039 | AM13: 1.2478642 | AN13: 1.6077296 | AO13: 0.52382242 | AP13: 1.5992844 | AQ13: 0.77763966 | AR13: 0.92346384 | AS13: 0.93824381 | AT13: 0.80201005 | AU13: 0.80786687
... A63: TTT | B63: 1.1465698 | C63: 1.5330098 | D63: 0 | E63: 0 | F63: 1.2779976 | G63: 1.6435451 | H63: 1.4933101 | I63: 1.1526965 | J63: 1.5625382 | K63: 1.6115098 | L63: 1.0975777 | M63: 1.6992623 | N63: 1.6612346 | O63: 1.2258786 | P63: 1.2441648 | Q63: 0.5766491 | R63: 1.3049365 | S63: 0.90606045 | T63: 1.2750498 | U63: 1.5327527 | V63: 0.99786875 | W63: 1.3999162 | X63: 1.0645507 | Y63: 1.2577514 | Z63: 1.0111504 | AA63: 1.0089725 | AB63: 0.71760326 | AC63: 0.70626695 | AD63: 1.6897588 | AE63: 1.551225 | AF63: 1.5479168 | AG63: 1.8342667 | AH63: 1.4416388 | AI63: 1.135451 | AJ63: 1.1244314 | AK63: 1.3806403 | AL63: 1.3609676 | AM63: 1.520108 | AN63: 1.3528005 | AO63: 0.7323119 | AP63: 1.7178392 | AQ63: 1.1331817 | AR63: 0.93328604 | AS63: 0.95309771 | AT63: 0.82910161 | AU63: 0.82559922

Sheet 全部菌密码子mean
B1: ASV45:s__unclassified_g__Escherichia-Shigella | C1: ASV1833:s__unclassified_g__Enterococcus | D1: ASV3729:s__Cloacibacillus_porcorum | E1: ASV31:s__Lactobacillus_vaginalis_g__Bacillus | F1: ASV17:s__uncultured_bacterium_g__Sharpea | G1: ASV9:s__unclassified_g__Romboutsia | H1: ASV73:s__unclassified_g__Turicibacter | I1: ASV1517:s__unclassified_g__Escherichia-Shigella | J1: ASV7:s__unclassified_g__Lactobacillus | K1: ASV30:s__unclassified_g__Clostridium_sensu_stricto_1 | L1: ASV21:s__Clostridium_scindens | M1: ASV54:s__unclassified_g__Clostridium_sensu_stricto_1 | N1: ASV33:s__gut_metagenome_g__norank_f__norank | O1: ASV1834:s__unclassified_f__Lachnospiraceae | P1: ASV28:s__uncultured_prokaryote_g__Christensenellaceae_R-7_group | Q1: ASV3787:s__uncultured_organism_g__UCG-002 | R1: ASV8:s__unclassified_g__Coprococcus | S1: ASV4:s__uncultured_spirochete_g__Christensenellaceae_R-7_group | T1: ASV1831:s__Eubacterium_coprostanoligenes | U1: ASV1555:s__unclassified_g__Enterococcus | V1: ASV1853:s__unclassified_g__Lactobacillus | W1: ASV22:s__unclassified_g__Lactobacillus | X1: ASV7036:s__unclassified_g__Bacteroides | Y1: ASV2:s__unclassified_g__Lactobacillus | Z1: ASV77:s__unclassified_g__Lactobacillus | AA1: ASV167:s__unclassified_g__Collinsella | AB1: ASV1540:s__unclassified_g__Megasphaera | AC1: ASV3402:s__unclassified_g__Megasphaera | AD1: ASV2874:s__unclassified_g__Fusobacterium | AE1: ASV2996:s__unclassified_g__Fusobacterium | AF1: ASV318:s__unclassified_g__Peptostreptococcus | AG1: ASV2586:s__unclassified_g__Campylobacter | AH1: ASV1515:s__unclassified_g__Streptococcus | AI1: ASV5:s__unclassified_g__UCG-002 | AJ1: ASV2860:s__unclassified_g__Phascolarctobacterium | AK1: ASV48:s__unclassified_g__Blautia | AL1: ASV38:s__unclassified_g__Blautia | AM1: ASV2839:s__Pasteurella_aerogenes | AN1: ASV1527:s__Lactobacillus_vaginalis_g__Bacillus | AO1: ASV172:s__uncultured_bacterium_g__Mogibacterium | AP1: ASV1089:s__Fusobacterium_gastrosuis | AQ1: ASV3058:s__uncultured_bacterium_g__Allisonella | AR1: H6_PBMC | AS1: H7_PBMC | AT1: W10_PBMC | AU1: W6_PBMC
A2: allAA_AT3 | B2: 0.9089904 | C2: 1.4144161 | D2: 0.19386722 | E2: 0.7168454 | F2: 1.4279897 | G2: 1.7084742 | H2: 1.5096558 | I2: 0.91146862 | J2: 1.5319888 | K2: 1.6989296 | L2: 0.92000512 | M2: 1.7197577 | N2: 1.6101518 | O2: 0.87471586 | P2: 0.79976534 | Q2: 0.29372803 | R2: 1.1500348 | S2: 0.76655069 | T2: 1.2509115 | U2: 1.4138069 | V2: 0.73486264 | W2: 0.97840061 | X2: 1.0953516 | Y2: 1.35846 | Z2: 0.75518654 | AA2: 0.47886589 | AB2: 0.66405032 | AC2: 0.65751558 | AD2: 1.7174321 | AE2: 1.3802257 | AF2: 1.4534231 | AG2: 1.534955 | AH2: 1.4180846 | AI2: 1.0424684 | AJ2: 0.95884198 | AK2: 1.2308953 | AL2: 1.2039935 | AM2: 1.2348929 | AN2: 1.294389 | AO2: 0.73680724 | AP2: 1.6900434 | AQ2: 1.0261746 | AR2: 0.78361957 | AS2: 0.80302758 | AT2: 0.68292307 | AU2: 0.68045617
A3: allAA_GC3 | B3: 1.0970769 | C3: 0.55795612 | D3: 0.52654164 | E3: 0.33536491 | F3: 0.54347763 | G3: 0.24429415 | H3: 0.45636711 | I3: 1.0944335 | J3: 0.4325453 | K3: 0.25447514 | L3: 1.0853279 | M3: 0.2322585 | N3: 0.34917143 | O3: 1.1336364 | P3: 1.2135836 | Q3: 1.7533568 | R3: 0.83996285 | S3: 1.2490126 | T3: 0.73236104 | U3: 0.55860602 | V3: 1.2828132 | W3: 1.0230393 | X3: 0.89829164 | Y3: 0.61764266 | Z3: 1.2611344 | AA3: 1.5558764 | AB3: 1.3583463 | AC3: 1.3653167 | AD3: 0.23473906 | AE3: 0.59442591 | AF3: 0.51634874 | AG3: 0.42938136 | AH3: 0.55404309 | AI3: 0.9547004 | AJ3: 1.0439019 | AK3: 0.75371173 | AL3: 0.78240694 | AM3: 0.7494476 | AN3: 0.68598507 | AO3: 1.2807389 | AP3: 0.26395375 | AQ3: 0.97208042 | AR3: 1.1308058 | AS3: 1.1101039 | AT3: 1.2382154 | AU3: 1.2408467

Sheet alljun
A1: asv | C1: ASV45 | D1: ASV1833 | E1: ASV3729 | F1: ASV31 | G1: ASV17 | H1: ASV9 | I1: ASV73 | J1: ASV1517 | K1: ASV7 | L1: ASV30 | M1: ASV21 | N1: ASV54 | O1: ASV33 | P1: ASV1834 | Q1: ASV28 | R1: ASV3787 | S1: ASV8 | T1: ASV4 | U1: ASV1831 | V1: ASV1555 | W1: ASV1853 | X1: ASV22 | Y1: ASV7036 | Z1: ASV2 | AA1: ASV77 | AB1: ASV167 | AC1: ASV1540 | AD1: ASV3402 | AE1: ASV2874 | AF1: ASV2996 | AG1: ASV318 | AH1: ASV2586 | AI1: ASV1515 | AJ1: ASV5 | AK1: ASV2860 | AL1: ASV48 | AM1: ASV38 | AN1: ASV2839 | AO1: ASV1527 | AP1: ASV172 | AQ1: ASV1089 | AR1: ASV3058 | AS1: #N/A | AT1: #N/A | AU1: #N/A | AV1: #N/A
A2: HW_name | C2: H_CE_GCA_000005845.2 | D2: H_CE_GCA_000407565.1 | E2: H_CE_GCA_001701045.1 | F2: H_CE_GCA_003703885.1 | G2: H_CE_GCA_009695655.1 | H2: H_CE_GCA_012317385.1 | I2: H_CE_GCA_013046825.1 | J2: H_CE_GCA_013374815.1 | K2: H_CE_GCA_014058685.1 | L2: H_CE_GCA_020138775.1 | M2: H_CE_GCA_020892115.1 | N2: H_CE_GCA_021412605.1 | O2: H_CE_GCA_022010015.1 | P2: H_CE_GCA_022845955.1 | Q2: H_CE_GCA_022846015.1 | R2: H_CE_GCA_022846095.1 | S2: H_CE_GCA_025149785.1 | T2: H_CE_GCA_900163975.1 | U2: H_CE_GCA_900167205.1 | V2: H_CE_GCA_900474605.1 | W2: W_CE_GCA_000056065.1 | X2: W_CE_GCA_014898655.1 | Y2: W_CE_GCA_000025985.1 | Z2: W_CE_GCA_000194115.1 | AA2: W_CE_GCA_001908415.1 | AB2: W_CE_GCA_002736145.1 | AC2: W_CE_GCA_003006415.1 | AD2: W_CE_GCA_003010495.1 | AE2: W_CE_GCA_003019315.1 | AF2: W_CE_GCA_003732525.1 | AG2: W_CE_GCA_009695815.1 | AH2: W_CE_GCA_009730395.1 | AI2: W_CE_GCA_013267695.1 | AJ2: W_CE_GCA_014982935.1 | AK2: W_CE_GCA_023497905.1 | AL2: W_CE_GCA_025147765.1 | AM2: W_CE_GCA_025148125.1 | AN2: W_CE_GCA_025264445.1 | AO2: W_CE_GCA_025311515.1 | AP2: W_CE_GCA_029224645.1 | AQ2: W_CE_GCA_034174805.1 | AR2: W_CE_GCA_900103425.1 | AS2: H6_PBMC | AT2: H7_PBMC | AU2: W10_PBMC | AV2: W6_PBMC
A3: name | C3: GCA_000005845.2 | D3: GCA_000407565.1 | E3: GCA_001701045.1 | F3: GCA_003703885.1 | G3: GCA_009695655.1 | H3: GCA_012317385.1 | I3: GCA_013046825.1 | J3: GCA_013374815.1 | K3: GCA_014058685.1 | L3: GCA_020138775.1 | M3: GCA_020892115.1 | N3: GCA_021412605.1 | O3: GCA_022010015.1 | P3: GCA_022845955.1 | Q3: GCA_022846015.1 | R3: GCA_022846095.1 | S3: GCA_025149785.1 | T3: GCA_900163975.1 | U3: GCA_900167205.1 | V3: GCA_900474605.1 | W3: GCA_000056065.1 | X3: GCA_014898655.1 | Y3: GCA_000025985.1 | Z3: GCA_000194115.1 | AA3: GCA_001908415.1 | AB3: GCA_002736145.1 | AC3: GCA_003006415.1 | AD3: GCA_003010495.1 | AE3: GCA_003019315.1 | AF3: GCA_003732525.1 | AG3: GCA_009695815.1 | AH3: GCA_009730395.1 | AI3: GCA_013267695.1 | AJ3: GCA_014982935.1 | AK3: GCA_023497905.1 | AL3: GCA_025147765.1 | AM3: GCA_025148125.1 | AN3: GCA_025264445.1 | AO3: GCA_025311515.1 | AP3: GCA_029224645.1 | AQ3: GCA_034174805.1 | AR3: GCA_900103425.1 | AS3: H6_PBMC | AT3: H7_PBMC | AU3: W10_PBMC | AV3: W6_PBMC
C4: ASV45:g__Escherichia-Shigella_s__unclassified_g__Escherichia-Shigella | D4: ASV1833:g__Enterococcus_s__unclassified_g__Enterococcus | E4: ASV3729:g__Cloacibacillus_s__Cloacibacillus_porcorum | F4: ASV31:g__Bacillus_s__Lactobacillus_vaginalis_g__Bacillus | G4: ASV17:g__Sharpea_s__uncultured_bacterium_g__Sharpea | H4: ASV9:g__Romboutsia_s__unclassified_g__Romboutsia | I4: ASV73:g__Turicibacter_s__unclassified_g__Turicibacter | J4: ASV1517:g__Escherichia-Shigella_s__unclassified_g__Escherichia-Shigella | K4: ASV7:g__Lactobacillus_s__unclassified_g__Lactobacillus | L4: ASV30:g__Clostridium_sensu_stricto_1_s__unclassified_g__Clostridium_sensu_stricto_1 | M4: ASV21:g__Lachnoclostridium_s__Clostridium_scindens | N4: ASV54:g__Clostridium_sensu_stricto_1_s__unclassified_g__Clostridium_sensu_stricto_1 | O4: ASV33:g__norank_f__norank_o__Clostridia_vadinBB60_group_s__gut_metagenome_g__norank_f__norank | P4: ASV1834:g__unclassified_f__Lachnospiraceae_s__unclassified_f__Lachnospiraceae | Q4: ASV28:g__Christensenellaceae_R-7_group_s__uncultured_prokaryote_g__Christensenellaceae_R-7_group | R4: ASV3787:g__UCG-002_s__uncultured_organism_g__UCG-002 | S4: ASV8:g__Coprococcus_s__unclassified_g__Coprococcus | T4: ASV4:g__Christensenellaceae_R-7_group_s__uncultured_spirochete_g__Christensenellaceae_R-7_group | U4: ASV1831:g__norank_f__Eubacterium_coprostanoligenes_group_s__Eubacterium_coprostanoligenes | V4: ASV1555:g__Enterococcus_s__unclassified_g__Enterococcus | W4: ASV1853:g__Lactobacillus_s__unclassified_g__Lactobacillus | X4: ASV22:g__Lactobacillus_s__unclassified_g__Lactobacillus | Y4: ASV7036:g__Bacteroides_s__unclassified_g__Bacteroides | Z4: ASV2:g__Lactobacillus_s__unclassified_g__Lactobacillus | AA4: ASV77:g__Lactobacillus_s__unclassified_g__Lactobacillus | AB4: ASV167:g__Collinsella_s__unclassified_g__Collinsella | AC4: ASV1540:g__Megasphaera_s__unclassified_g__Megasphaera | AD4: ASV3402:g__Megasphaera_s__unclassified_g__Megasphaera | AE4: ASV2874:g__Fusobacterium_s__unclassified_g__Fusobacterium | AF4: ASV2996:g__Fusobacterium_s__unclassified_g__Fusobacterium | AG4: ASV318:g__Peptostreptococcus_s__unclassified_g__Peptostreptococcus | AH4: ASV2586:g__Campylobacter_s__unclassified_g__Campylobacter | AI4: ASV1515:g__Streptococcus_s__unclassified_g__Streptococcus | AJ4: ASV5:g__UCG-002_s__unclassified_g__UCG-002 | AK4: ASV2860:g__Phascolarctobacterium_s__unclassified_g__Phascolarctobacterium | AL4: ASV48:g__Blautia_s__unclassified_g__Blautia | AM4: ASV38:g__Blautia_s__unclassified_g__Blautia | AN4: ASV2839:g__Pasteurella_s__Pasteurella_aerogenes | AO4: ASV1527:g__Bacillus_s__Lactobacillus_vaginalis_g__Bacillus | AP4: ASV172:g__Mogibacterium_s__uncultured_bacterium_g__Mogibacterium | AQ4: ASV1089:g__Fusobacterium_s__Fusobacterium_gastrosuis | AR4: ASV3058:g__Allisonella_s__uncultured_bacterium_g__Allisonella
A5: AAA | B5: =IF(OR(RIGHT(A5,1)="A",RIGHT(A5,1)="T"),"A/T","G/C") -> A/T | C5: 1.5344933 | D5: 1.552725 | E5: 0 | F5: 1.0956245 | G5: 1.1003009 | H5: 1.5187491 | I5: 1.5591946 | J5: 1.5296648 | K5: 1.2350621 | L5: 1.3844375 | M5: 0.86034145 | N5: 1.4183298 | O5: 1.1789639 | P5: 1.1190215 | Q5: 1.1158873 | R5: 0.45727555 | S5: 1.2088429 | T5: 1.0443849 | U5: 1.1214768 | V5: 1.552149 | W5: 0.50928423 | X5: 0.8899004 | Y5: 1.2818064 | Z5: 0.94544423 | AA5: 0.51771298 | AB5: 0.32621684 | AC5: 1.0685378 | AD5: 1.0705512 | AE5: 1.6205278 | AF5: 1.5278473 | AG5: 1.2526677 | AH5: 1.6783762 | AI5: 1.5970184 | AJ5: 1.4902614 | AK5: 0.92982259 | AL5: 1.3642961 | AM5: 1.2745115 | AN5: 1.7985108 | AO5: 0.8443391 | AP5: 0.75492687 | AQ5: 1.6843118 | AR5: 0.88084687 | AS5: 0.82420333 | AT5: 0.84761225 | AU5: 0.72913694 | AV5: 0.72889925
A6: AAC | B6: =IF(OR(RIGHT(A6,1)="A",RIGHT(A6,1)="T"),"A/T","G/C") -> G/C | C6: 1.1056573 | D6: 0.44191523 | E6: 1.3276645 | F6: 0 | G6: 0.44965649 | H6: 0.33113056 | I6: 0.41820066 | J6: 1.0947583 | K6: 0.49387857 | L6: 0.34829941 | M6: 0.74777448 | N6: 0.2615033 | O6: 0.23711186 | P6: 0.83726107 | Q6: 1.0548613 | R6: 1.6368538 | S6: 0.66831659 | T6: 0.95215697 | U6: 0.93924179 | V6: 0.44187311 | W6: 1.3166014 | X6: 0.9463945 | Y6: 0.80780773 | Z6: 0.83513347 | AA6: 1.2931713 | AB6: 1.5653435 | AC6: 1.0367471 | AD6: 1.0558359 | AE6: 0.30417004 | AF6: 0.41853426 | AG6: 0.46567213 | AH6: 0.2755878 | AI6: 0.5642554 | AJ6: 0.93756226 | AK6: 0.9635142 | AL6: 0.63390209 | AM6: 0.65698822 | AN6: 0.57416653 | AO6: 0.76651457 | AP6: 1.1311703 | AQ6: 0.26299282 | AR6: 0.71951558 | AS6: 1.0953025 | AT6: 1.0755309 | AU6: 1.2093849 | AV6: 1.2117844
A7: AAG | B7: =IF(OR(RIGHT(A7,1)="A",RIGHT(A7,1)="T"),"A/T","G/C") -> G/C | C7: 0.4655067 | D7: 0.44727505 | E7: 0 | F7: 0.90437554 | G7: 0.8996991 | H7: 0.48125091 | I7: 0.44080537 | J7: 0.4703352 | K7: 0.76493793 | L7: 0.61556252 | M7: 1.1396586 | N7: 0.58167015 | O7: 0.82103611 | P7: 0.88097848 | Q7: 0.8841127 | R7: 1.5427245 | S7: 0.79115708 | T7: 0.95561514 | U7: 0.87852324 | V7: 0.44785105 | W7: 1.4907158 | X7: 1.1100996 | Y7: 0.71819363 | Z7: 1.0545558 | AA7: 1.482287 | AB7: 1.6737832 | AC7: 0.93146217 | AD7: 0.92944883 | AE7: 0.37947216 | AF7: 0.47215268 | AG7: 0.74733231 | AH7: 0.32162383 | AI7: 0.4029816 | AJ7: 0.5097386 | AK7: 1.0701774 | AL7: 0.63570392 | AM7: 0.72548854 | AN7: 0.2014892 | AO7: 1.1556609 | AP7: 1.2450731 | AQ7: 0.31568819 | AR7: 1.1191531 | AS7: 1.1757967 | AT7: 1.1523878 | AU7: 1.2708631 | AV7: 1.2711007
A8: AAT | B8: =IF(OR(RIGHT(A8,1)="A",RIGHT(A8,1)="T"),"A/T","G/C") -> A/T | C8: 0.89434271 | D8: 1.5580848 | E8: 0.6723355 | F8: 0 | G8: 1.5503435 | H8: 1.6688694 | I8: 1.5817993 | J8: 0.90524175 | K8: 1.5061214 | L8: 1.6517006 | M8: 1.2522255 | N8: 1.7384967 | O8: 1.7628881 | P8: 1.1627389 | Q8: 0.94513874 | R8: 0.36314621 | S8: 1.3316834 | T8: 1.047843 | U8: 1.0607582 | V8: 1.5581269 | W8: 0.68339855 | X8: 1.0536055 | Y8: 1.1921923 | Z8: 1.1648665 | AA8: 0.70682875 | AB8: 0.43465653 | AC8: 0.9632529 | AD8: 0.9441641 | AE8: 1.69583 | AF8: 1.5814657 | AG8: 1.5343279 | AH8: 1.7244122 | AI8: 1.4357446 | AJ8: 1.0624377 | AK8: 1.0364858 | AL8: 1.3660979 | AM8: 1.3430118 | AN8: 1.4258335 | AO8: 1.2334854 | AP8: 0.86882972 | AQ8: 1.7370072 | AR8: 1.2804844 | AS8: 0.90469753 | AT8: 0.92446909 | AU8: 0.79061514 | AV8: 0.78821564
A9: ACA | B9: =IF(OR(RIGHT(A9,1)="A",RIGHT(A9,1)="T"),"A/T","G/C") -> A/T | C9: 0.51469138 | D9: 1.2775862 | E9: 0 | F9: 0 | G9: 2.2324906 | H9: 1.7933592 | I9: 1.7010858 | J9: 0.52534263 | K9: 1.0469924 | L9: 1.6724142 | M9: 1.0441376 | N9: 1.8077399 | O9: 1.7989976 | P9: 0.87104425 | Q9: 0.79379342 | R9: 0.21643251 | S9: 1.695286 | T9: 0.82251533 | U9: 1.9253987 | V9: 1.2742812 | W9: 0.31146774 | X9: 0.36462414 | Y9: 1.0646685 | Z9: 0.7603421 | AA9: 0.31869402 | AB9: 0.2060243 | AC9: 0.51982011 | AD9: 0.50972855 | AE9: 1.7680812 | AF9: 1.441668 | AG9: 1.7432823 | AH9: 1.2536876 | AI9: 1.7040754 | AJ9: 1.8633721 | AK9: 0.77867461 | AL9: 1.8813726 | AM9: 1.8431514 | AN9: 0.78504673 | AO9: 0.97127704 | AP9: 0.59505286 | AQ9: 1.972937 | AR9: 1.0422389 | AS9: 1.075281 | AT9: 1.097374 | AU9: 0.95089291 | AV9: 0.94136558
A10: ACC | B10: =IF(OR(RIGHT(A10,1)="A",RIGHT(A10,1)="T"),"A/T","G/C") -> G/C | C10: 1.7506286 | D10: 0.76143335 | E10: 0 | F10: 0 | G10: 0.35337741 | H10: 0.12223404 | I10: 0.45786628 | J10: 1.7348147 | K10: 0.45526833 | L10: 0.25379995 | M10: 1.1443052 | N10: 0.14512864 | O10: 0.41382856 | P10: 1.6153628 | Q10: 0.92791865 | R10: 2.8040785 | S10: 0.89875482 | T10: 1.3480238 | U10: 0.80722073 | V10: 0.76117119 | W10: 1.6818394 | X10: 1.1420238 | Y10: 1.1646848 | Z10: 0.7357618 | AA10: 1.6638255 | AB10: 2.0034393 | AC10: 1.3025976 | AD10: 1.3097075 | AE10: 0.12168678 | AF10: 0.72801925 | AG10: 0.29052382 | AH10: 0.72013285 | AI10: 0.53819373 | AJ10: 1.1400634 | AK10: 1.4469099 | AL10: 0.71101927 | AM10: 0.80768374 | AN10: 1.4485119 | AO10: 0.89344707 | AP10: 1.9434114 | AQ10: 0.16483179 | AR10: 1.5702854 | AS10: 1.4166976 | AT10: 1.3920074 | AU10: 1.578409 | AV10: 1.5754043
A11: ACG | B11: =IF(OR(RIGHT(A11,1)="A",RIGHT(A11,1)="T"),"A/T","G/C") -> G/C | C11: 1.0725052 | D11: 0.78112741 | E11: 0 | F11: 0 | G11: 0.46363283 | H11: 0.16386877 | I11: 0.91863379 | J11: 1.0806369 | K11: 0.31045558 | L11: 0.060896423 | M11: 1.2672999 | N11: 0.11871302 | O11: 0.21616759 | P11: 1.096354 | Q11: 1.9430625 | R11: 0.83626771 | S11: 0.73897278 | T11: 1.2650393 | U11: 0.34964899 | V11: 0.78259035 | W11: 0.79565327 | X11: 1.6469848 | Y11: 0.70528006 | Z11: 0.50490972 | AA11: 0.78243282 | AB11: 1.5072946 | AC11: 1.7919442 | AD11: 1.7868934 | AE11: 0.041343669 | AF11: 0.71942261 | AG11: 0.45502387 | AH11: 0.28348149 | AI11: 0.64233054 | AJ11: 0.43375617 | AK11: 0.78165302 | AL11: 0.62132042 | AM11: 0.46648107 | AN11: 0.77239396 | AO11: 0.63043548 | AP11: 1.004361 | AQ11: 0.14669893 | AR11: 0.65559935 | AS11: 0.55933646 | AT11: 0.53974269 | AU11: 0.64597244 | AV11: 0.66047694
A12: ACT | B12: =IF(OR(RIGHT(A12,1)="A",RIGHT(A12,1)="T"),"A/T","G/C") -> A/T | C12: 0.66217474 | D12: 1.1798531 | E12: 0 | F12: 0 | G12: 0.95049916 | H12: 1.920538 | I12: 0.92241417 | J12: 0.6592058 | K12: 2.1872837 | L12: 2.0128894 | M12: 0.54425732 | N12: 1.9284184 | O12: 1.5710063 | P12: 0.41723894 | Q12: 0.3352254 | R12: 0.14322129 | S12: 0.66698643 | T12: 0.56442162 | U12: 0.91773155 | V12: 1.1819573 | W12: 1.2110395 | X12: 0.8463672 | Y12: 1.0653666 | Z12: 1.9989864 | AA12: 1.2350477 | AB12: 0.2832418 | AC12: 0.3856381 | AD12: 0.39367052 | AE12: 2.0688884 | AF12: 1.1108901 | AG12: 1.51117 | AH12: 1.7426981 | AI12: 1.1154004 | AJ12: 0.56280832 | AK12: 0.99276247 | AL12: 0.78628773 | AM12: 0.88268374 | AN12: 0.99404745 | AO12: 1.5048404 | AP12: 0.45717475 | AQ12: 1.7155322 | AR12: 0.73187627 | AS12: 0.94868493 | AT12: 0.97087592 | AU12: 0.82472566 | AV12: 0.82275323
A13: AGA | B13: =IF(OR(RIGHT(A13,1)="A",RIGHT(A13,1)="T"),"A/T","G/C") -> A/T | C13: 0.21333008 | D13: 1.1085595 | E13: 0 | F13: 0.46743804 | G13: 2.1507092 | H13: 4.9494198 | I13: 1.0592135 | J13: 0.22055788 | K13: 1.9959153 | L13: 5.1465397 | M13: 1.4813218 | N13: 4.9301618 | O13: 3.4057454 | P13: 1.0439228 | Q13: 0.56284348 | R13: 0.13977768 | S13: 1.9790772 | T13: 0.76583682 | U13: 2.8377993 | V13: 1.1081948 | W13: 0.97058824 | X13: 0.42386003 | Y13: 0.82834924 | Z13: 1.7803473 | AA13: 1.0101963 | AB13: 0.090549592 | AC13: 0.24602622 | AD13: 0.24292563 | AE13: 5.3436626 | AF13: 3.0704132 | AG13: 4.4608331 | AH13: 3.1309334 | AI13: 0.69197442 | AJ13: 1.625922 | AK13: 0.79962936 | AL13: 2.038995 | AM13: 2.1077663 | AN13: 0.41943872 | AO13: 0.43845743 | AP13: 1.1297387 | AQ13: 5.0807683 | AR13: 1.3217935 | AS13: 1.214156 | AT13: 1.2785368 | AU13: 1.0274827 | AV13: 1.0239431
A14: AGC | B14: =IF(OR(RIGHT(A14,1)="A",RIGHT(A14,1)="T"),"A/T","G/C") -> G/C | C14: 1.6704955 | D14: 0.70664202 | E14: 0 | F14: 0 | G14: 0.76668833 | H14: 0.46283478 | I14: 0.41793973 | J14: 1.658763 | K14: 0.64170564 | L14: 0.51752079 | M14: 1.5822501 | N14: 0.49070632 | O14: 0.86965398 | P14: 1.6090639 | Q14: 1.7633126 | R14: 2.018353 | S14: 1.034682 | T14: 1.242341 | U14: 1.2037545 | V14: 0.70701701 | W14: 2.0319047 | X14: 1.4182496 | Y14: 0.92798815 | Z14: 0.90089474 | AA14: 2.0016269 | AB14: 1.6064423 | AC14: 1.6467848 | AD14: 1.6248377 | AE14: 0.32473735 | AF14: 0.66604423 | AG14: 0.67258258 | AH14: 1.3385707 | AI14: 0.84659977 | AJ14: 1.4932739 | AK14: 2.2699561 | AL14: 0.95723847 | AM14: 1.0350585 | AN14: 1.1051922 | AO14: 0.7876251 | AP14: 1.4975636 | AQ14: 0.39546064 | AR14: 1.0489909 | AS14: 1.4353908 | AT14: 1.4128015 | AU14: 1.604821 | AV14: 1.6032355
A15: AGG | B15: =IF(OR(RIGHT(A15,1)="A",RIGHT(A15,1)="T"),"A/T","G/C") -> G/C | C15: 0.11825465 | D15: 0.20936475 | E15: 0 | F15: 0.20944414 | G15: 0.32291667 | H15: 0.59569674 | I15: 0.22083348 | J15: 0.12766633 | K15: 0.27407223 | L15: 0.58369413 | M15: 1.3433801 | N15: 0.63620878 | O15: 0.76179493 | P15: 1.2335059 | Q15: 0.9292184 | R15: 0.47153372 | S15: 0.5749934 | T15: 0.83352296 | U15: 0.48707785 | V15: 0.21027515 | W15: 0.32506394 | X15: 0.15049934 | Y15: 0.42399547 | Z15: 0.20327544 | AA15: 0.32781035 | AB15: 0.25905899 | AC15: 0.20042869 | AD15: 0.19574369 | AE15: 0.39143533 | AF15: 0.48132231 | AG15: 0.92821588 | AH15: 0.58489965 | AI15: 0.19781308 | AJ15: 0.27879344 | AK15: 0.3270601 | AL15: 0.50693536 | AM15: 0.70199645 | AN15: 0.060180338 | AO15: 0.24020306 | AP15: 0.18943858 | AQ15: 0.50975306 | AR15: 0.59285972 | AS15: 1.1964193 | AT15: 1.2143534 | AU15: 1.208372 | AV15: 1.2079256
A16: AGT | B16: =IF(OR(RIGHT(A16,1)="A",RIGHT(A16,1)="T"),"A/T","G/C") -> A/T | C16: 0.9021513 | D16: 1.7672887 | E16: 0 | F16: 0 | G16: 1.4540227 | H16: 1.8204617 | I16: 1.5965562 | J16: 0.91770624 | K16: 1.7109246 | L16: 1.7464985 | M16: 0.69048899 | N16: 1.8811042 | O16: 1.6731653 | P16: 0.68506088 | Q16: 0.57562415 | R16: 0.19554541 | S16: 1.197236 | T16: 0.49089058 | U16: 0.66554503 | V16: 1.7665553 | W16: 0.60804501 | X16: 1.0685248 | Y16: 1.148847 | Z16: 1.3710078 | AA16: 0.63358641 | AB16: 0.28282774 | AC16: 0.6601586 | AD16: 0.64817833 | AE16: 1.8883886 | AF16: 1.3861916 | AG16: 1.2327629 | AH16: 1.9333293 | AI16: 1.2730417 | AJ16: 0.80998363 | AK16: 0.80542419 | AL16: 1.254657 | AM16: 1.1535039 | AN16: 1.2478642 | AO16: 1.6077296 | AP16: 0.52382242 | AQ16: 1.5992844 | AR16: 0.77763966 | AS16: 0.92346384 | AT16: 0.93824381 | AU16: 0.80201005 | AV16: 0.80786687
... A66: TTT | B66: =IF(OR(RIGHT(A66,1)="A",RIGHT(A66,1)="T"),"A/T","G/C") -> A/T | C66: 1.1465698 | D66: 1.5330098 | E66: 0 | F66: 0 | G66: 1.2779976 | H66: 1.6435451 | I66: 1.4933101 | J66: 1.1526965 | K66: 1.5625382 | L66: 1.6115098 | M66: 1.0975777 | N66: 1.6992623 | O66: 1.6612346 | P66: 1.2258786 | Q66: 1.2441648 | R66: 0.5766491 | S66: 1.3049365 | T66: 0.90606045 | U66: 1.2750498 | V66: 1.5327527 | W66: 0.99786875 | X66: 1.3999162 | Y66: 1.0645507 | Z66: 1.2577514 | AA66: 1.0111504 | AB66: 1.0089725 | AC66: 0.71760326 | AD66: 0.70626695 | AE66: 1.6897588 | AF66: 1.551225 | AG66: 1.5479168 | AH66: 1.8342667 | AI66: 1.4416388 | AJ66: 1.135451 | AK66: 1.1244314 | AL66: 1.3806403 | AM66: 1.3609676 | AN66: 1.520108 | AO66: 1.3528005 | AP66: 0.7323119 | AQ66: 1.7178392 | AR66: 1.1331817 | AS66: 0.93328604 | AT66: 0.95309771 | AU66: 0.82910161 | AV66: 0.82559922
A67: allAA_AT3 | C67: =AVERAGEIF($B5:$B66,"A/T",C5:C66) -> 0.9089904 | D67: =AVERAGEIF($B5:$B66,"A/T",D5:D66) -> 1.4144161 | E67: =AVERAGEIF($B5:$B66,"A/T",E5:E66) -> 0.19386722 | F67: =AVERAGEIF($B5:$B66,"A/T",F5:F66) -> 0.7168454 | G67: =AVERAGEIF($B5:$B66,"A/T",G5:G66) -> 1.4279897 | H67: =AVERAGEIF($B5:$B66,"A/T",H5:H66) -> 1.7084742 | I67: =AVERAGEIF($B5:$B66,"A/T",I5:I66) -> 1.5096558 | J67: =AVERAGEIF($B5:$B66,"A/T",J5:J66) -> 0.91146862 | ... AV67: =AVERAGEIF($B5:$B66,"A/T",AV5:AV66) -> 0.68045617
A68: allAA_GC3 | C68: =AVERAGEIF($B5:$B66,"G/C",C5:C66) -> 1.0970769 | D68: =AVERAGEIF($B5:$B66,"G/C",D5:D66) -> 0.55795612 | E68: =AVERAGEIF($B5:$B66,"G/C",E5:E66) -> 0.52654164 | F68: =AVERAGEIF($B5:$B66,"G/C",F5:F66) -> 0.33536491 | G68: =AVERAGEIF($B5:$B66,"G/C",G5:G66) -> 0.54347763 | H68: =AVERAGEIF($B5:$B66,"G/C",H5:H66) -> 0.24429415 | I68: =AVERAGEIF($B5:$B66,"G/C",I5:I66) -> 0.45636711 | J68: =AVERAGEIF($B5:$B66,"G/C",J5:J66) -> 1.0944335 | ... AV68: =AVERAGEIF($B5:$B66,"G/C",AV5:AV66) -> 1.2408467

Sheet 精氨酸
A1: name | B1: ASV8:s__unclassified_g__Coprococcus | C1: ASV1555:s__unclassified_g__Enterococcus | D1: ASV1831:s__Eubacterium_coprostanoligenes | E1: ASV54:s__unclassified_g__Clostridium_sensu_stricto_1 | F1: ASV21:s__Clostridium_scindens | G1: ASV30:s__unclassified_g__Clostridium_sensu_stricto_1 | H1: ASV73:s__unclassified_g__Turicibacter | I1: ASV9:s__unclassified_g__Romboutsia | J1: ASV17:s__uncultured_bacterium_g__Sharpea | K1: ASV5:s__unclassified_g__UCG-002 | L1: ASV4:s__uncultured_spirochete_g__Christensenellaceae_R-7_group | M1: ASV28:s__uncultured_prokaryote_g__Christensenellaceae_R-7_group | N1: ASV3787:s__uncultured_organism_g__UCG-002 | O1: ASV1834:s__unclassified_f__Lachnospiraceae | P1: ASV22:s__unclassified_g__Lactobacillus | Q1: ASV3402:s__unclassified_g__Megasphaera | R1: ASV1540:s__unclassified_g__Megasphaera | S1: ASV77:s__unclassified_g__Lactobacillus | T1: ASV1853:s__unclassified_g__Lactobacillus | U1: ASV1089:s__Fusobacterium_gastrosuis | V1: ASV38:s__unclassified_g__Blautia | W1: ASV48:s__unclassified_g__Blautia | X1: ASV1515:s__unclassified_g__Streptococcus | Y1: ASV2996:s__unclassified_g__Fusobacterium | Z1: ASV2874:s__unclassified_g__Fusobacterium | AA1: ASV167:s__unclassified_g__Collinsella | AB1: ASV2:s__unclassified_g__Lactobacillus | AC1: H6_PBMC | AD1: H7_PBMC | AE1: W10_PBMC | AF1: W6_PBMC
A2: AGA | B2: 1.9790772 | C2: 1.1081948 | D2: 2.8377993 | E2: 4.9301618 | F2: 1.4813218 | G2: 5.1465397 | H2: 1.0592135 | I2: 4.9494198 | J2: 2.1507092 | K2: 1.625922 | L2: 0.76583682 | M2: 0.56284348 | N2: 0.13977768 | O2: 1.0439228 | P2: 0.42386003 | Q2: 0.24292563 | R2: 0.24602622 | S2: 1.0101963 | T2: 0.97058824 | U2: 5.0807683 | V2: 2.1077663 | W2: 2.038995 | X2: 0.69197442 | Y2: 3.0704132 | Z2: 5.3436626 | AA2: 0.090549592 | AB2: 1.7803473 | AC2: 1.214156 | AD2: 1.2785368 | AE2: 1.0274827 | AF2: 1.0239431
A3: CGT | B3: 1.4220793 | C3: 2.5024979 | D3: 1.4710639 | E3: 0.27448595 | F3: 0.75584107 | G3: 0.20921868 | H3: 2.8302317 | I3: 0.28928692 | J3: 2.4277482 | K3: 1.6037081 | L3: 0.63150587 | M3: 1.0521067 | N3: 0.26363227 | O3: 0.92630396 | P3: 1.4975614 | Q3: 0.95854771 | R3: 0.95738106 | S3: 0.61305124 | T3: 0.59820972 | U3: 0.22509354 | V3: 1.3694993 | W3: 1.6834598 | X3: 3.3380648 | Y3: 0.69289256 | Z3: 0.21928126 | AA3: 1.3195061 | AB3: 2.3772159 | AC3: 0.51341834 | AD3: 0.51324374 | AE3: 0.47045757 | AF3: 0.46659962
A4: CGA | B4: 0.42642225 | C4: 0.75810902 | D4: 0.54986523 | E4: 0.11680253 | F4: 0.333568 | G4: 0.037367615 | H4: 1.0944308 | I4: 0.12526755 | J4: 0.36059397 | K4: 0.39812875 | L4: 0.54137339 | M4: 0.28073478 | N4: 0.097566471 | O4: 0.20478287 | P4: 0.69280793 | Q4: 0.23205098 | R4: 0.24485705 | S4: 0.21055315 | T4: 0.19974425 | U4: 0.13619356 | V4: 0.42719766 | W4: 0.5902905 | X4: 0.60854137 | Y4: 1.3013774 | Z4: 0.032709275 | AA4: 0.26825922 | AB4: 0.48861693 | AC4: 0.73988064 | AD4: 0.74700273 | AE4: 0.67515448 | AF4: 0.67645921
A5: CGC | B5: 0.67677616 | C5: 1.0952203 | D5: 0.58601554 | E5: 0.029930648 | F5: 0.96031152 | G5: 0.017984414 | H5: 0.63909125 | I5: 0.034020502 | J5: 0.61879433 | K5: 1.042505 | L5: 2.0777908 | M5: 1.967586 | N5: 2.5764609 | O5: 0.89562798 | P5: 1.8561586 | Q5: 2.8605589 | R5: 2.835565 | S5: 1.5936783 | T5: 1.5861893 | U5: 0.023946121 | V5: 0.72520121 | W5: 0.64066998 | X5: 1.0148133 | Y5: 0.14369146 | Z5: 0.007531741 | AA5: 3.7638609 | AB5: 0.91757401 | AC5: 1.0439061 | AD5: 0.99537166 | AE5: 1.1858972 | AF5: 1.177639
A6: CGG | B6: 0.92065168 | C6: 0.32570278 | D6: 0.068178215 | E6: 0.012410269 | F6: 1.1255775 | G6: 0.005195497 | H6: 0.15619929 | I6: 0.006308438 | J6: 0.11923759 | K6: 1.0509428 | L6: 1.1499701 | M6: 1.2075107 | N6: 2.451029 | O6: 1.6958564 | P6: 1.3791128 | Q6: 1.5101731 | R6: 1.515742 | S6: 2.2447107 | T6: 2.3202046 | U6: 0.024245448 | V6: 0.66833908 | W6: 0.53964931 | X6: 0.14879307 | Y6: 0.31030303 | Z6: 0.005379815 | AA6: 0.29876523 | AB6: 0.23297039 | AC6: 1.2922196 | AD6: 1.2514917 | AE6: 1.432636 | AF6: 1.4474336
A7: AGG | B7: 0.5749934 | C7: 0.21027515 | D7: 0.48707785 | E7: 0.63620878 | F7: 1.3433801 | G7: 0.58369413 | H7: 0.22083348 | I7: 0.59569674 | J7: 0.32291667 | K7: 0.27879344 | L7: 0.83352296 | M7: 0.9292184 | N7: 0.47153372 | O7: 1.2335059 | P7: 0.15049934 | Q7: 0.19574369 | R7: 0.20042869 | S7: 0.32781035 | T7: 0.32506394 | U7: 0.50975306 | V7: 0.70199645 | W7: 0.50693536 | X7: 0.19781308 | Y7: 0.48132231 | Z7: 0.39143533 | AA7: 0.25905899 | AB7: 0.20327544 | AC7: 1.1964193 | AD7: 1.2143534 | AE7: 1.208372 | AF7: 1.2079256
A8: AT3 | B8: 1.2758596 | C8: 1.4562672 | D8: 1.6195761 | E8: 1.7738168 | F8: 0.85691028 | G8: 1.7977087 | H8: 1.661292 | I8: 1.7879914 | J8: 1.6463505 | K8: 1.2092529 | L8: 0.64623869 | M8: 0.63189497 | N8: 0.16699214 | O8: 0.72500322 | P8: 0.87140977 | Q8: 0.47784144 | R8: 0.48275478 | S8: 0.61126689 | T8: 0.58951407 | U8: 1.8140185 | V8: 1.3014878 | W8: 1.4375818 | X8: 1.5461935 | Y8: 1.6882277 | Z8: 1.8652177 | AA8: 0.5594383 | AB8: 1.5487267 | AC8: 0.82248499 | AD8: 0.84626108 | AE8: 0.72436493 | AF8: 0.72233397
A9: GC3 | B9: 0.72414041 | C9: 0.54373276 | D9: 0.38042387 | E9: 0.22618323 | F9: 1.1430897 | G9: 0.20229135 | H9: 0.33870801 | I9: 0.21200856 | J9: 0.35364953 | K9: 0.79074707 | L9: 1.3537613 | M9: 1.368105 | N9: 1.8330079 | O9: 1.2749968 | P9: 1.1285902 | Q9: 1.5221586 | R9: 1.5172452 | S9: 1.3887331 | T9: 1.4104859 | U9: 0.18598154 | V9: 0.69851225 | W9: 0.56241821 | X9: 0.45380648 | Y9: 0.31177227 | Z9: 0.1347823 | AA9: 1.4405617 | AB9: 0.45127328 | AC9: 1.177515 | AD9: 1.1537389 | AE9: 1.2756351 | AF9: 1.277666
A10: allAA_AT3 | B10: 1.1500348 | C10: 1.4138069 | D10: 1.2509115 | E10: 1.7197577 | F10: 0.92000512 | G10: 1.6989296 | H10: 1.5096558 | I10: 1.7084742 | J10: 1.4279897 | K10: 1.0424684 | L10: 1.6900434 | M10: 1.2039935 | N10: 1.2308953 | O10: 1.4180846 | P10: 1.3802257 | Q10: 1.7174321 | R10: 0.47886589 | S10: 1.35846 | T10: 0.76655069 | U10: 0.79976534 | V10: 0.29372803 | W10: 0.87471586 | X10: 0.97840061 | Y10: 0.65751558 | Z10: 0.66405032 | AA10: 0.75518654 | AB10: 0.73486264 | AC10: 0.78361957 | AD10: 0.80302758 | AE10: 0.68292307 | AF10: 0.68045617
A11: allAA_GC3 | B11: 0.83996285 | C11: 0.55860602 | D11: 0.73236104 | E11: 0.2322585 | F11: 1.0853279 | G11: 0.25447514 | H11: 0.45636711 | I11: 0.24429415 | J11: 0.54347763 | K11: 0.9547004 | L11: 0.26395375 | M11: 0.78240694 | N11: 0.75371173 | O11: 0.55404309 | P11: 0.59442591 | Q11: 0.23473906 | R11: 1.5558764 | S11: 0.61764266 | T11: 1.2490126 | U11: 1.2135836 | V11: 1.7533568 | W11: 1.1336364 | X11: 1.0230393 | Y11: 1.3653167 | Z11: 1.3583463 | AA11: 1.2611344 | AB11: 1.2828132 | AC11: 1.1308058 | AD11: 1.1101039 | AE11: 1.2382154 | AF11: 1.2408467

Sheet Arg
A1: Arg | C1: ASV8 | D1: ASV1555 | E1: ASV1831 | F1: ASV54 | G1: ASV21 | H1: ASV30 | I1: ASV73 | J1: ASV9 | K1: ASV17 | L1: ASV5 | M1: ASV4 | N1: ASV28 | O1: ASV3787 | P1: ASV1834 | Q1: ASV22 | R1: ASV3402 | S1: ASV1540 | T1: ASV77 | U1: ASV1853 | V1: ASV1089 | W1: ASV38 | X1: ASV48 | Y1: ASV1515 | Z1: ASV2996 | AA1: ASV2874 | AB1: ASV167 | AC1: ASV2 | AD1: H6_PBMC | AE1: H7_PBMC | AF1: W10_PBMC | AG1: W6_PBMC
A2: name | C2: H_CE_GCA_025149785.1 | D2: H_CE_GCA_900474605.1 | E2: H_CE_GCA_900167205.1 | F2: H_CE_GCA_021412605.1 | G2: H_CE_GCA_020892115.1 | H2: H_CE_GCA_020138775.1 | I2: H_CE_GCA_013046825.1 | J2: H_CE_GCA_012317385.1 | K2: H_CE_GCA_009695655.1 | L2: H_CE_GCA_014982935.1 | M2: H_CE_GCA_900163975.1 | N2: H_CE_GCA_022846015.1 | O2: H_CE_GCA_022846095.1 | P2: H_CE_GCA_022845955.1 | Q2: W_CE_GCA_014898655.1 | R2: W_CE_GCA_003010495.1 | S2: W_CE_GCA_003006415.1 | T2: W_CE_GCA_001908415.1 | U2: W_CE_GCA_000056065.1 | V2: W_CE_GCA_034174805.1 | W2: W_CE_GCA_025148125.1 | X2: W_CE_GCA_025147765.1 | Y2: W_CE_GCA_013267695.1 | Z2: W_CE_GCA_003732525.1 | AA2: W_CE_GCA_003019315.1 | AB2: W_CE_GCA_002736145.1 | AC2: W_CE_GCA_000194115.1 | AD2: H6_PBMC | AE2: H7_PBMC | AF2: W10_PBMC | AG2: W6_PBMC
A3: AAA | B3: =IF(OR(RIGHT(A3,1)="A",RIGHT(A3,1)="T"),"A/T","G/C") -> A/T | C3: 1.2088429 | D3: 1.552149 | E3: 1.1214768 | F3: 1.4183298 | G3: 0.86034145 | H3: 1.3844375 | I3: 1.5591946 | J3: 1.5187491 | K3: 1.1003009 | L3: 1.4902614 | M3: 1.6843118 | N3: 1.2745115 | O3: 1.3642961 | P3: 1.5970184 | Q3: 1.5278473 | R3: 1.6205278 | S3: 0.32621684 | T3: 0.94544423 | U3: 1.0443849 | V3: 1.1158873 | W3: 0.45727555 | X3: 1.1190215 | Y3: 0.8899004 | Z3: 1.0705512 | AA3: 1.0685378 | AB3: 0.51771298 | AC3: 0.50928423 | AD3: 0.82420333 | AE3: 0.84761225 | AF3: 0.72913694 | AG3: 0.72889925
A4: AAC | B4: =IF(OR(RIGHT(A4,1)="A",RIGHT(A4,1)="T"),"A/T","G/C") -> G/C | C4: 0.66831659 | D4: 0.44187311 | E4: 0.93924179 | F4: 0.2615033 | G4: 0.74777448 | H4: 0.34829941 | I4: 0.41820066 | J4: 0.33113056 | K4: 0.44965649 | L4: 0.93756226 | M4: 0.26299282 | N4: 0.65698822 | O4: 0.63390209 | P4: 0.5642554 | Q4: 0.41853426 | R4: 0.30417004 | S4: 1.5653435 | T4: 0.83513347 | U4: 0.95215697 | V4: 1.0548613 | W4: 1.6368538 | X4: 0.83726107 | Y4: 0.9463945 | Z4: 1.0558359 | AA4: 1.0367471 | AB4: 1.2931713 | AC4: 1.3166014 | AD4: 1.0953025 | AE4: 1.0755309 | AF4: 1.2093849 | AG4: 1.2117844
A5: AAG | B5: =IF(OR(RIGHT(A5,1)="A",RIGHT(A5,1)="T"),"A/T","G/C") -> G/C | C5: 0.79115708 | D5: 0.44785105 | E5: 0.87852324 | F5: 0.58167015 | G5: 1.1396586 | H5: 0.61556252 | I5: 0.44080537 | J5: 0.48125091 | K5: 0.8996991 | L5: 0.5097386 | M5: 0.31568819 | N5: 0.72548854 | O5: 0.63570392 | P5: 0.4029816 | Q5: 0.47215268 | R5: 0.37947216 | S5: 1.6737832 | T5: 1.0545558 | U5: 0.95561514 | V5: 0.8841127 | W5: 1.5427245 | X5: 0.88097848 | Y5: 1.1100996 | Z5: 0.92944883 | AA5: 0.93146217 | AB5: 1.482287 | AC5: 1.4907158 | AD5: 1.1757967 | AE5: 1.1523878 | AF5: 1.2708631 | AG5: 1.2711007
A6: AAT | B6: =IF(OR(RIGHT(A6,1)="A",RIGHT(A6,1)="T"),"A/T","G/C") -> A/T | C6: 1.3316834 | D6: 1.5581269 | E6: 1.0607582 | F6: 1.7384967 | G6: 1.2522255 | H6: 1.6517006 | I6: 1.5817993 | J6: 1.6688694 | K6: 1.5503435 | L6: 1.0624377 | M6: 1.7370072 | N6: 1.3430118 | O6: 1.3660979 | P6: 1.4357446 | Q6: 1.5814657 | R6: 1.69583 | S6: 0.43465653 | T6: 1.1648665 | U6: 1.047843 | V6: 0.94513874 | W6: 0.36314621 | X6: 1.1627389 | Y6: 1.0536055 | Z6: 0.9441641 | AA6: 0.9632529 | AB6: 0.70682875 | AC6: 0.68339855 | AD6: 0.90469753 | AE6: 0.92446909 | AF6: 0.79061514 | AG6: 0.78821564
A7: ACA | B7: =IF(OR(RIGHT(A7,1)="A",RIGHT(A7,1)="T"),"A/T","G/C") -> A/T | C7: 1.695286 | D7: 1.2742812 | E7: 1.9253987 | F7: 1.8077399 | G7: 1.0441376 | H7: 1.6724142 | I7: 1.7010858 | J7: 1.7933592 | K7: 2.2324906 | L7: 1.8633721 | M7: 1.972937 | N7: 1.8431514 | O7: 1.8813726 | P7: 1.7040754 | Q7: 1.441668 | R7: 1.7680812 | S7: 0.2060243 | T7: 0.7603421 | U7: 0.82251533 | V7: 0.79379342 | W7: 0.21643251 | X7: 0.87104425 | Y7: 0.36462414 | Z7: 0.50972855 | AA7: 0.51982011 | AB7: 0.31869402 | AC7: 0.31146774 | AD7: 1.075281 | AE7: 1.097374 | AF7: 0.95089291 | AG7: 0.94136558
A8: ACC | B8: =IF(OR(RIGHT(A8,1)="A",RIGHT(A8,1)="T"),"A/T","G/C") -> G/C | C8: 0.89875482 | D8: 0.76117119 | E8: 0.80722073 | F8: 0.14512864 | G8: 1.1443052 | H8: 0.25379995 | I8: 0.45786628 | J8: 0.12223404 | K8: 0.35337741 | L8: 1.1400634 | M8: 0.16483179 | N8: 0.80768374 | O8: 0.71101927 | P8: 0.53819373 | Q8: 0.72801925 | R8: 0.12168678 | S8: 2.0034393 | T8: 0.7357618 | U8: 1.3480238 | V8: 0.92791865 | W8: 2.8040785 | X8: 1.6153628 | Y8: 1.1420238 | Z8: 1.3097075 | AA8: 1.3025976 | AB8: 1.6638255 | AC8: 1.6818394 | AD8: 1.4166976 | AE8: 1.3920074 | AF8: 1.578409 | AG8: 1.5754043
A9: ACG | B9: =IF(OR(RIGHT(A9,1)="A",RIGHT(A9,1)="T"),"A/T","G/C") -> G/C | C9: 0.73897278 | D9: 0.78259035 | E9: 0.34964899 | F9: 0.11871302 | G9: 1.2672999 | H9: 0.060896423 | I9: 0.91863379 | J9: 0.16386877 | K9: 0.46363283 | L9: 0.43375617 | M9: 0.14669893 | N9: 0.46648107 | O9: 0.62132042 | P9: 0.64233054 | Q9: 0.71942261 | R9: 0.041343669 | S9: 1.5072946 | T9: 0.50490972 | U9: 1.2650393 | V9: 1.9430625 | W9: 0.83626771 | X9: 1.096354 | Y9: 1.6469848 | Z9: 1.7868934 | AA9: 1.7919442 | AB9: 0.78243282 | AC9: 0.79565327 | AD9: 0.55933646 | AE9: 0.53974269 | AF9: 0.64597244 | AG9: 0.66047694
A10: ACT | B10: =IF(OR(RIGHT(A10,1)="A",RIGHT(A10,1)="T"),"A/T","G/C") -> A/T | C10: 0.66698643 | D10: 1.1819573 | E10: 0.91773155 | F10: 1.9284184 | G10: 0.54425732 | H10: 2.0128894 | I10: 0.92241417 | J10: 1.920538 | K10: 0.95049916 | L10: 0.56280832 | M10: 1.7155322 | N10: 0.88268374 | O10: 0.78628773 | P10: 1.1154004 | Q10: 1.1108901 | R10: 2.0688884 | S10: 0.2832418 | T10: 1.9989864 | U10: 0.56442162 | V10: 0.3352254 | W10: 0.14322129 | X10: 0.41723894 | Y10: 0.8463672 | Z10: 0.39367052 | AA10: 0.3856381 | AB10: 1.2350477 | AC10: 1.2110395 | AD10: 0.94868493 | AE10: 0.97087592 | AF10: 0.82472566 | AG10: 0.82275323
A11: AGA | B11: =IF(OR(RIGHT(A11,1)="A",RIGHT(A11,1)="T"),"A/T","G/C") -> A/T | C11: 1.9790772 | D11: 1.1081948 | E11: 2.8377993 | F11: 4.9301618 | G11: 1.4813218 | H11: 5.1465397 | I11: 1.0592135 | J11: 4.9494198 | K11: 2.1507092 | L11: 1.625922 | M11: 5.0807683 | N11: 2.1077663 | O11: 2.038995 | P11: 0.69197442 | Q11: 3.0704132 | R11: 5.3436626 | S11: 0.090549592 | T11: 1.7803473 | U11: 0.76583682 | V11: 0.56284348 | W11: 0.13977768 | X11: 1.0439228 | Y11: 0.42386003 | Z11: 0.24292563 | AA11: 0.24602622 | AB11: 1.0101963 | AC11: 0.97058824 | AD11: 1.214156 | AE11: 1.2785368 | AF11: 1.0274827 | AG11: 1.0239431
A12: AGC | B12: =IF(OR(RIGHT(A12,1)="A",RIGHT(A12,1)="T"),"A/T","G/C") -> G/C | C12: 1.034682 | D12: 0.70701701 | E12: 1.2037545 | F12: 0.49070632 | G12: 1.5822501 | H12: 0.51752079 | I12: 0.41793973 | J12: 0.46283478 | K12: 0.76668833 | L12: 1.4932739 | M12: 0.39546064 | N12: 1.0350585 | O12: 0.95723847 | P12: 0.84659977 | Q12: 0.66604423 | R12: 0.32473735 | S12: 1.6064423 | T12: 0.90089474 | U12: 1.242341 | V12: 1.7633126 | W12: 2.018353 | X12: 1.6090639 | Y12: 1.4182496 | Z12: 1.6248377 | AA12: 1.6467848 | AB12: 2.0016269 | AC12: 2.0319047 | AD12: 1.4353908 | AE12: 1.4128015 | AF12: 1.604821 | AG12: 1.6032355
A13: AGG | B13: =IF(OR(RIGHT(A13,1)="A",RIGHT(A13,1)="T"),"A/T","G/C") -> G/C | C13: 0.5749934 | D13: 0.21027515 | E13: 0.48707785 | F13: 0.63620878 | G13: 1.3433801 | H13: 0.58369413 | I13: 0.22083348 | J13: 0.59569674 | K13: 0.32291667 | L13: 0.27879344 | M13: 0.50975306 | N13: 0.70199645 | O13: 0.50693536 | P13: 0.19781308 | Q13: 0.48132231 | R13: 0.39143533 | S13: 0.25905899 | T13: 0.20327544 | U13: 0.83352296 | V13: 0.9292184 | W13: 0.47153372 | X13: 1.2335059 | Y13: 0.15049934 | Z13: 0.19574369 | AA13: 0.20042869 | AB13: 0.32781035 | AC13: 0.32506394 | AD13: 1.1964193 | AE13: 1.2143534 | AF13: 1.208372 | AG13: 1.2079256
A14: AGT | B14: =IF(OR(RIGHT(A14,1)="A",RIGHT(A14,1)="T"),"A/T","G/C") -> A/T | C14: 1.197236 | D14: 1.7665553 | E14: 0.66554503 | F14: 1.8811042 | G14: 0.69048899 | H14: 1.7464985 | I14: 1.5965562 | J14: 1.8204617 | K14: 1.4540227 | L14: 0.80998363 | M14: 1.5992844 | N14: 1.1535039 | O14: 1.254657 | P14: 1.2730417 | Q14: 1.3861916 | R14: 1.8883886 | S14: 0.28282774 | T14: 1.3710078 | U14: 0.49089058 | V14: 0.57562415 | W14: 0.19554541 | X14: 0.68506088 | Y14: 1.0685248 | Z14: 0.64817833 | AA14: 0.6601586 | AB14: 0.63358641 | AC14: 0.60804501 | AD14: 0.92346384 | AE14: 0.93824381 | AF14: 0.80201005 | AG14: 0.80786687
... A64: TTT | B64: =IF(OR(RIGHT(A64,1)="A",RIGHT(A64,1)="T"),"A/T","G/C") -> A/T | C64: 1.3049365 | D64: 1.5327527 | E64: 1.2750498 | F64: 1.6992623 | G64: 1.0975777 | H64: 1.6115098 | I64: 1.4933101 | J64: 1.6435451 | K64: 1.2779976 | L64: 1.135451 | M64: 1.7178392 | N64: 1.3609676 | O64: 1.3806403 | P64: 1.4416388 | Q64: 1.551225 | R64: 1.6897588 | S64: 1.0089725 | T64: 1.2577514 | U64: 0.90606045 | V64: 1.2441648 | W64: 0.5766491 | X64: 1.2258786 | Y64: 1.3999162 | Z64: 0.70626695 | AA64: 0.71760326 | AB64: 1.0111504 | AC64: 0.99786875 | AD64: 0.93328604 | AE64: 0.95309771 | AF64: 0.82910161 | AG64: 0.82559922
A65: AT3 | C65: =AVERAGEIF($B:$B,"A/T",C:C) -> 1.1500348 | D65: =AVERAGEIF($B:$B,"A/T",D:D) -> 1.4138069 | E65: =AVERAGEIF($B:$B,"A/T",E:E) -> 1.2509115 | F65: =AVERAGEIF($B:$B,"A/T",F:F) -> 1.7197577 | G65: =AVERAGEIF($B:$B,"A/T",G:G) -> 0.92000512 | H65: =AVERAGEIF($B:$B,"A/T",H:H) -> 1.6989296 | I65: =AVERAGEIF($B:$B,"A/T",I:I) -> 1.5096558 | J65: =AVERAGEIF($B:$B,"A/T",J:J) -> 1.7084742 | K65: =AVERAGEIF($B:$B,"A/T",K:K) -> 1.4279897 | L65: =AVERAGEIF($B:$B,"A/T",L:L) -> 1.0424684 | M65: =AVERAGEIF($B:$B,"A/T",M:M) -> 1.6900434 | N65: =AVERAGEIF($B:$B,"A/T",N:N) -> 1.2039935 | O65: =AVERAGEIF($B:$B,"A/T",O:O) -> 1.2308953 | P65: =AVERAGEIF($B:$B,"A/T",P:P) -> 1.4180846 | Q65: =AVERAGEIF($B:$B,"A/T",Q:Q) -> 1.3802257 | R65: =AVERAGEIF($B:$B,"A/T",R:R) -> 1.7174321 | S65: =AVERAGEIF($B:$B,"A/T",S:S) -> 0.47886589 | T65: =AVERAGEIF($B:$B,"A/T",T:T) -> 1.35846 | U65: =AVERAGEIF($B:$B,"A/T",U:U) -> 0.76655069 | V65: =AVERAGEIF($B:$B,"A/T",V:V) -> 0.79976534 | W65: =AVERAGEIF($B:$B,"A/T",W:W) -> 0.29372803 | X65: =AVERAGEIF($B:$B,"A/T",X:X) -> 0.87471586 | Y65: =AVERAGEIF($B:$B,"A/T",Y:Y) -> 0.97840061 | Z65: =AVERAGEIF($B:$B,"A/T",Z:Z) -> 0.65751558 | AA65: =AVERAGEIF($B:$B,"A/T",AA:AA) -> 0.66405032 | AB65: =AVERAGEIF($B:$B,"A/T",AB:AB) -> 0.75518654 | AC65: =AVERAGEIF($B:$B,"A/T",AC:AC) -> 0.73486264 | AD65: =AVERAGEIF($B:$B,"A/T",AD:AD) -> 0.78361957 | AE65: =AVERAGEIF($B:$B,"A/T",AE:AE) -> 0.80302758 | AF65: =AVERAGEIF($B:$B,"A/T",AF:AF) -> 0.68292307 | AG65: =AVERAGEIF($B:$B,"A/T",AG:AG) -> 0.68045617
A66: GC3 | C66: =AVERAGEIF($B:$B,"G/C",C:C) -> 0.83996285 | D66: =AVERAGEIF($B:$B,"G/C",D:D) -> 0.55860602 | E66: =AVERAGEIF($B:$B,"G/C",E:E) -> 0.73236104 | F66: =AVERAGEIF($B:$B,"G/C",F:F) -> 0.2322585 | G66: =AVERAGEIF($B:$B,"G/C",G:G) -> 1.0853279 | H66: =AVERAGEIF($B:$B,"G/C",H:H) -> 0.25447514 | I66: =AVERAGEIF($B:$B,"G/C",I:I) -> 0.45636711 | J66: =AVERAGEIF($B:$B,"G/C",J:J) -> 0.24429415 | K66: =AVERAGEIF($B:$B,"G/C",K:K) -> 0.54347763 | L66: =AVERAGEIF($B:$B,"G/C",L:L) -> 0.9547004 | M66: =AVERAGEIF($B:$B,"G/C",M:M) -> 0.26395375 | N66: =AVERAGEIF($B:$B,"G/C",N:N) -> 0.78240694 | O66: =AVERAGEIF($B:$B,"G/C",O:O) -> 0.75371173 | P66: =AVERAGEIF($B:$B,"G/C",P:P) -> 0.55404309 | Q66: =AVERAGEIF($B:$B,"G/C",Q:Q) -> 0.59442591 | R66: =AVERAGEIF($B:$B,"G/C",R:R) -> 0.23473906 | S66: =AVERAGEIF($B:$B,"G/C",S:S) -> 1.5558764 | T66: =AVERAGEIF($B:$B,"G/C",T:T) -> 0.61764266 | U66: =AVERAGEIF($B:$B,"G/C",U:U) -> 1.2490126 | V66: =AVERAGEIF($B:$B,"G/C",V:V) -> 1.2135836 | W66: =AVERAGEIF($B:$B,"G/C",W:W) -> 1.7533568 | X66: =AVERAGEIF($B:$B,"G/C",X:X) -> 1.1336364 | Y66: =AVERAGEIF($B:$B,"G/C",Y:Y) -> 1.0230393 | Z66: =AVERAGEIF($B:$B,"G/C",Z:Z) -> 1.3653167 | AA66: =AVERAGEIF($B:$B,"G/C",AA:AA) -> 1.3583463 | AB66: =AVERAGEIF($B:$B,"G/C",AB:AB) -> 1.2611344 | AC66: =AVERAGEIF($B:$B,"G/C",AC:AC) -> 1.2828132 | AD66: =AVERAGEIF($B:$B,"G/C",AD:AD) -> 1.1308058 | AE66: =AVERAGEIF($B:$B,"G/C",AE:AE) -> 1.1101039 | AF66: =AVERAGEIF($B:$B,"G/C",AF:AF) -> 1.2382154 | AG66: =AVERAGEIF($B:$B,"G/C",AG:AG) -> 1.2408467

Sheet Sheet1
A1: asv
A3: ASV8 | B3: =VLOOKUP(A3,[1]ALL!$G:$I,2,FALSE) -> g__Coprococcus | C3: =VLOOKUP(A3,[1]ALL!$G:$I,3,FALSE) -> s__unclassified_g__Coprococcus | D3: =A3&":"&C3 -> ASV8:s__unclassified_g__Coprococcus | E3: ASV8:s__unclassified_g__Coprococcus
A4: ASV1555 | B4: =VLOOKUP(A4,[1]ALL!$G:$I,2,FALSE) -> g__Enterococcus | C4: =VLOOKUP(A4,[1]ALL!$G:$I,3,FALSE) -> s__unclassified_g__Enterococcus | D4: =A4&":"&C4 -> ASV1555:s__unclassified_g__Enterococcus | E4: ASV1555:s__unclassified_g__Enterococcus
A5: ASV1831 | B5: =VLOOKUP(A5,[1]ALL!$G:$I,2,FALSE) -> g__norank_f__Eubacterium_coprostanoligenes_group | C5: =VLOOKUP(A5,[1]ALL!$G:$I,3,FALSE) -> s__Eubacterium_coprostanoligenes | D5: =A5&":"&C5 -> ASV1831:s__Eubacterium_coprostanoligenes | E5: ASV1831:s__Eubacterium_coprostanoligenes
A6: ASV54 | B6: =VLOOKUP(A6,[1]ALL!$G:$I,2,FALSE) -> g__Clostridium_sensu_stricto_1 | C6: =VLOOKUP(A6,[1]ALL!$G:$I,3,FALSE) -> s__unclassified_g__Clostridium_sensu_stricto_1 | D6: =A6&":"&C6 -> ASV54:s__unclassified_g__Clostridium_sensu_stricto_1 | E6: ASV54:s__unclassified_g__Clostridium_sensu_stricto_1
A7: ASV21 | B7: =VLOOKUP(A7,[1]ALL!$G:$I,2,FALSE) -> g__Lachnoclostridium | C7: =VLOOKUP(A7,[1]ALL!$G:$I,3,FALSE) -> s__Clostridium_scindens | D7: =A7&":"&C7 -> ASV21:s__Clostridium_scindens | E7: ASV21:s__Clostridium_scindens
A8: ASV30 | B8: =VLOOKUP(A8,[1]ALL!$G:$I,2,FALSE) -> g__Clostridium_sensu_stricto_1 | C8: =VLOOKUP(A8,[1]ALL!$G:$I,3,FALSE) -> s__unclassified_g__Clostridium_sensu_stricto_1 | D8: =A8&":"&C8 -> ASV30:s__unclassified_g__Clostridium_sensu_stricto_1 | E8: ASV30:s__unclassified_g__Clostridium_sensu_stricto_1
A9: ASV73 | B9: =VLOOKUP(A9,[1]ALL!$G:$I,2,FALSE) -> g__Turicibacter | C9: =VLOOKUP(A9,[1]ALL!$G:$I,3,FALSE) -> s__unclassified_g__Turicibacter | D9: =A9&":"&C9 -> ASV73:s__unclassified_g__Turicibacter | E9: ASV73:s__unclassified_g__Turicibacter
A10: ASV9 | B10: =VLOOKUP(A10,[1]ALL!$G:$I,2,FALSE) -> g__Romboutsia | C10: =VLOOKUP(A10,[1]ALL!$G:$I,3,FALSE) -> s__unclassified_g__Romboutsia | D10: =A10&":"&C10 -> ASV9:s__unclassified_g__Romboutsia | E10: ASV9:s__unclassified_g__Romboutsia
A11: ASV17 | B11: =VLOOKUP(A11,[1]ALL!$G:$I,2,FALSE) -> g__Sharpea | C11: =VLOOKUP(A11,[1]ALL!$G:$I,3,FALSE) -> s__uncultured_bacterium_g__Sharpea | D11: =A11&":"&C11 -> ASV17:s__uncultured_bacterium_g__Sharpea | E11: ASV17:s__uncultured_bacterium_g__Sharpea
A12: ASV5 | B12: =VLOOKUP(A12,[1]ALL!$G:$I,2,FALSE) -> g__UCG-002 | C12: =VLOOKUP(A12,[1]ALL!$G:$I,3,FALSE) -> s__unclassified_g__UCG-002 | D12: =A12&":"&C12 -> ASV5:s__unclassified_g__UCG-002 | E12: ASV5:s__unclassified_g__UCG-002
A13: ASV4 | B13: =VLOOKUP(A13,[1]ALL!$G:$I,2,FALSE) -> g__Christensenellaceae_R-7_group | C13: =VLOOKUP(A13,[1]ALL!$G:$I,3,FALSE) -> s__uncultured_spirochete_g__Christensenellaceae_R-7_group | D13: =A13&":"&C13 -> ASV4:s__uncultured_spirochete_g__Christensenellaceae_R-7_group | E13: ASV4:s__uncultured_spirochete_g__Christensenellaceae_R-7_group
A14: ASV28 | B14: =VLOOKUP(A14,[1]ALL!$G:$I,2,FALSE) -> g__Christensenellaceae_R-7_group | C14: =VLOOKUP(A14,[1]ALL!$G:$I,3,FALSE) -> s__uncultured_prokaryote_g__Christensenellaceae_R-7_group | D14: =A14&":"&C14 -> ASV28:s__uncultured_prokaryote_g__Christensenellaceae_R-7_group | E14: ASV28:s__uncultured_prokaryote_g__Christensenellaceae_R-7_group
... A45: ASV3058 | B45: =VLOOKUP(A45,[1]ALL!$G:$I,2,FALSE) -> g__Allisonella | C45: =VLOOKUP(A45,[1]ALL!$G:$I,3,FALSE) -> s__uncultured_bacterium_g__Allisonella | D45: =A45&":"&C45 -> ASV3058:s__uncultured_bacterium_g__Allisonella | E45: ASV3058:s__uncultured_bacterium_g__Allisonella
A46: #N/A | B46: =VLOOKUP(A46,[1]ALL!$G:$I,2,FALSE) -> #N/A | C46: =VLOOKUP(A46,[1]ALL!$G:$I,3,FALSE) -> #N/A
A47: #N/A | B47: =VLOOKUP(A47,[1]ALL!$G:$I,2,FALSE) -> #N/A | C47: =VLOOKUP(A47,[1]ALL!$G:$I,3,FALSE) -> #N/A
A48: #N/A | B48: =VLOOKUP(A48,[1]ALL!$G:$I,2,FALSE) -> #N/A | C48: =VLOOKUP(A48,[1]ALL!$G:$I,3,FALSE) -> #N/A
A49: #N/A | B49: =VLOOKUP(A49,[1]ALL!$G:$I,2,FALSE) -> #N/A | C49: =VLOOKUP(A49,[1]ALL!$G:$I,3,FALSE) -> #N/A
C56: ASV45:s__unclassified_g__Escherichia-Shigella | D56: ASV1833:s__unclassified_g__Enterococcus | E56: ASV3729:s__Cloacibacillus_porcorum | F56: ASV31:s__Lactobacillus_vaginalis_g__Bacillus | G56: ASV17:s__uncultured_bacterium_g__Sharpea | H56: ASV9:s__unclassified_g__Romboutsia | I56: ASV73:s__unclassified_g__Turicibacter | J56: ASV1517:s__unclassified_g__Escherichia-Shigella | K56: ASV7:s__unclassified_g__Lactobacillus | L56: ASV30:s__unclassified_g__Clostridium_sensu_stricto_1 | M56: ASV21:s__Clostridium_scindens | N56: ASV54:s__unclassified_g__Clostridium_sensu_stricto_1 | O56: ASV33:s__gut_metagenome_g__norank_f__norank | P56: ASV1834:s__unclassified_f__Lachnospiraceae | Q56: ASV28:s__uncultured_prokaryote_g__Christensenellaceae_R-7_group | R56: ASV3787:s__uncultured_organism_g__UCG-002 | S56: ASV8:s__unclassified_g__Coprococcus | T56: ASV4:s__uncultured_spirochete_g__Christensenellaceae_R-7_group | U56: ASV1831:s__Eubacterium_coprostanoligenes | V56: ASV1555:s__unclassified_g__Enterococcus | W56: ASV1853:s__unclassified_g__Lactobacillus | X56: ASV22:s__unclassified_g__Lactobacillus | Y56: ASV7036:s__unclassified_g__Bacteroides | Z56: ASV2:s__unclassified_g__Lactobacillus | AA56: ASV77:s__unclassified_g__Lactobacillus | AB56: ASV167:s__unclassified_g__Collinsella | AC56: ASV1540:s__unclassified_g__Megasphaera | AD56: ASV3402:s__unclassified_g__Megasphaera | AE56: ASV2874:s__unclassified_g__Fusobacterium | AF56: ASV2996:s__unclassified_g__Fusobacterium | AG56: ASV318:s__unclassified_g__Peptostreptococcus | AH56: ASV2586:s__unclassified_g__Campylobacter | AI56: ASV1515:s__unclassified_g__Streptococcus | AJ56: ASV5:s__unclassified_g__UCG-002 | AK56: ASV2860:s__unclassified_g__Phascolarctobacterium | AL56: ASV48:s__unclassified_g__Blautia | AM56: ASV38:s__unclassified_g__Blautia | AN56: ASV2839:s__Pasteurella_aerogenes | AO56: ASV1527:s__Lactobacillus_vaginalis_g__Bacillus | AP56: ASV172:s__uncultured_bacterium_g__Mogibacterium | AQ56: ASV1089:s__Fusobacterium_gastrosuis | AR56: ASV3058:s__uncultured_bacterium_g__Allisonella
A57: ASV8
A58: ASV1555
A59: ASV1831
A60: ASV54
A61: ASV21
A62: ASV30
A63: ASV73
A64: ASV9
A65: ASV17
A66: ASV5
A67: ASV4
A68: ASV28
... A83: ASV2

Sheet 缬氨酸
A1: name | B1: H_CE_GCA_025149785.1 | C1: H_CE_GCA_900167205.1 | D1: H_CE_GCA_021412605.1 | E1: H_CE_GCA_020138775.1 | F1: H_CE_GCA_013046825.1 | G1: H_CE_GCA_012317385.1 | H1: H_CE_GCA_009695655.1 | I1: H_CE_GCA_900163975.1 | J1: H_CE_GCA_022846015.1 | K1: H_CE_GCA_021412605.1 | L1: H_CE_GCA_022846095.1 | M1: H_CE_GCA_000005845.2 | N1: H_CE_GCA_022845955.1 | O1: W_CE_GCA_034174805.1 | P1: W_CE_GCA_025311515.1 | Q1: W_CE_GCA_025148125.1 | R1: W_CE_GCA_025147765.1 | S1: W_CE_GCA_023497905.1 | T1: W_CE_GCA_014898655.1 | U1: W_CE_GCA_013267695.1 | V1: W_CE_GCA_003019315.1 | W1: W_CE_GCA_000194115.1 | X1: W_CE_GCA_025264445.1 | Y1: W_CE_GCA_003010495.1 | Z1: W_CE_GCA_003006415.1 | AA1: W_CE_GCA_002736145.1 | AB1: H6_PBMC | AC1: H7_PBMC | AD1: W10_PBMC | AE1: W6_PBMC
